Workbook

Sheet Instructions
D1: EJEMPLO | N1: BS USD rate
C2: FB Revenue Report | D2: Vacio | E2: Protocol | F2: Sponsor | G2: Allentown / Argentina | H2: Custom 2 | K2: Vacio | L2: Line description | M2: YYYY | N2: MM | O2: CURRENCY | P2: 40 % (sin hadling) | R2: 40 % (sin hadling) | S2: Vacio | T2: Not Applicable (solo para Allentown) | V2: no cambia | W2: no cambia
D3: grpcode | E3: el4 | F3: el4_name | G3: el4_sname | H3: name | I3: el2 | J3: el2_name | K3: el3 | L3: el3_name | M3: yr | N3: period | O3: curcode | P3: LOC AMT | Q3: Rate | R3: USD AMT | S3: cmpcode | T3: Discount Flag
A6: Selectable Table | B6: CUSTOMER | C6: Enter grpcode Name
B7: INVOICE_. | C7: Enter Invoice Number (FB/Manual Inv /CN)
A8: blank | B8: FISHER_JOB | C8: Enter Fisher Job Number GPM
B9: PROTOCOL | C9: Enter Protocol Number
B10: yr | C10: Enter Year
B11: period | C11: Enter Period Number
A12: Selectable Table | B12: PRODUCT | C12: Select Category of Revenue
B13: SUB-PRODUCT | C13: Enter Service
B14: DocValue | C14: Enter Total with VAT (Include Surcharge)
B15: DOC_CURRENCY | C15: Enter Currency Invoice
B16: USD Value | C16: Enter Total with VAT in SD Exchange Rate Balance sheet
B17: FISHER_LOC | C17: Enter Site
B18: PO. | C18: Enter PO Number (ONLY)
B19: doccode | C19: NA
B20: el4_name | C20: Enter Sponsor Name
B21: Home Currency | C21: Enter Total with VAT in SD Exchange Rate Balance sheet
B22: docdate | C22: Enter Billing Date
B23: ref1 | C23: NA
A24: Selectable Table | B24: el2 | C24: Enter Revenue Code
A25: Selectable Table | B25: el2_name | C25: Enter Revenue Code
B26: el3 | C26: NA
A29: Include :
A30: 1 | B30: Allentown Invoices 40% (Excluding handling fee)
A31: 2 | B31: Fisherbook Billing_ Local Clients
A32: 3 | B32: Manual Invoices / Rebill
A33: 4 | B33: Credit Notes
A34: 5 | B34: PTC Duties Adjustemnts
A35: 6 | B35: Surcharge lines
A36: 7 | B36: Revenue Adjustments (FX, per category or last 15days estimation)
A37: 8 | B37: Revenue Adjustments (Local Adj /Duty Adj/GNRE Adj)
A38: 9 | B38: Adjustment 606
A40: Don't Include:
A41: a. | B41: Allentown Invoices Full Amount
A42: b. | B42: Manual Invoices / Rebill Transfer Pricing
A43: c. | B43: Credit Notes Transfer Pricing
A49: Porque es importante?
A50: Informacion a equipo comercial para calculo rebate
...

Sheet Arg
A1: Vacio | B1: Protocol | C1: Element 4 short name | D1: Allentown / Argentina | E1: Custom 2 | H1: Vacio | I1: Line description | J1: YYYY | K1: MM | L1: CURRENCY | M1: 40 % (sin hadling) | O1: 40 % (sin hadling) | P1: Vacio | Q1: Not Applicable (solo para Allentown) | R1: Vacio | S1: Vacio
A2: grpcode | B2: el4 | C2: el4_name | D2: el4_sname | E2: name | F2: el2 | G2: el2_name | H2: el3 | I2: el3_name | J2: yr | K2: period | L2: curcode | M2: LOC AMT | N2: Rate | O2: USD AMT | P2: cmpcode | Q2: Discount Flag | R2: _ | S2: x
B3: Transfer Pricing 05-2026 | C3: Allentown | D3: Allentown | E3: Total Distribution | F3: 40700 | G3: Revenues - Third Parties | I3: Transfer Pricing | J3: 2026 | K3: 5 | L3: USD | M3: 632795.23 | N3: 1 | O3: =M3*N3 -> 632795.23 | P3: BSArgentina | Q3: Not Applicable | R3: =+VLOOKUP(E3,'Selectable Table'!B:C,2,0) -> Distribution | V3: Row Labels | W3: Sum of LOC AMT | Y3: HFM | Z3: DIF
B4: Transfer Pricing 05-2026 | C4: Allentown | D4: Allentown | E4: Total Duty | F4: 40700 | G4: Revenues - Third Parties | I4: Transfer Pricing | J4: 2026 | K4: 5 | L4: USD | M4: 939471.61 | N4: 1 | O4: =M4*N4 -> 939471.61 | P4: BSArgentina | Q4: Not Applicable | R4: =+VLOOKUP(E4,'Selectable Table'!B:C,2,0) -> Duties | V4: Total Distribution | W4: 691858 | Y4: 691858 | Z4: =Y4-W4 -> 0
B5: Transfer Pricing 05-2026 | C5: Allentown | D5: Allentown | E5: Total Freight | F5: 40700 | G5: Revenues - Third Parties | I5: Transfer Pricing | J5: 2026 | K5: 5 | L5: USD | M5: 553076.9 | N5: 1 | O5: =M5*N5 -> 553076.9 | P5: BSArgentina | Q5: Not Applicable | R5: =+VLOOKUP(E5,'Selectable Table'!B:C,2,0) -> Freight | V5: Total Duty | W5: -498649 | Y5: -498649 | Z5: =Y5-W5 -> 0
B6: Transfer Pricing 05-2026 | C6: Allentown | D6: Allentown | E6: Total Packaging | F6: 40700 | G6: Revenues - Third Parties | I6: Transfer Pricing | J6: 2026 | K6: 5 | L6: USD | M6: 11523.532 | N6: 1 | O6: =M6*N6 -> 11523.532 | P6: BSArgentina | Q6: Not Applicable | R6: =+VLOOKUP(E6,'Selectable Table'!B:C,2,0) -> Packaging | V6: Total Freight | W6: 529642 | Y6: 529642 | Z6: =Y6-W6 -> 0
B7: Transfer Pricing 05-2026 | C7: Allentown | D7: Allentown | E7: Total Return Drug | F7: 40700 | G7: Revenues - Third Parties | I7: Transfer Pricing | J7: 2026 | K7: 5 | L7: USD | M7: 53437.632 | N7: 1 | O7: =M7*N7 -> 53437.632 | P7: BSArgentina | Q7: Not Applicable | R7: =+VLOOKUP(E7,'Selectable Table'!B:C,2,0) -> ReturnDrug | V7: Total Packaging | W7: 36028 | Y7: 36028 | Z7: =Y7-W7 -> 0
B8: Transfer Pricing 05-2026 | C8: Allentown | D8: Allentown | E8: Total Storage | F8: 40700 | G8: Revenues - Third Parties | I8: Transfer Pricing | J8: 2026 | K8: 5 | L8: USD | M8: 399083.04 | N8: 1 | O8: =M8*N8 -> 399083.04 | P8: BSArgentina | Q8: Not Applicable | R8: =+VLOOKUP(E8,'Selectable Table'!B:C,2,0) -> Storage | V8: Total Return Drug | W8: 75325 | Y8: 75325 | Z8: =Y8-W8 -> 0
B9: Materiales pool Janssen | C9: Janssen | D9: Argentina | E9: Total Storage | F9: 40700 | G9: Revenues - Third Parties | I9: Non-Drug Storage Ambient (per Pallet) | J9: 2026 | K9: 5 | L9: USD | M9: 727.7774 | N9: 1 | O9: =M9*N9 -> 727.7774 | P9: BSArgentina | R9: =+VLOOKUP(E9,'Selectable Table'!B:C,2,0) -> Storage | V9: Total Storage | W9: 508279 | Y9: 508279 | Z9: =Y9-W9 -> 0
B10: 64091742PCR3001_anc_returns | C10: Janssen | D10: Argentina | E10: Total Storage | F10: 40700 | G10: Revenues - Third Parties | I10: Storage of Returns (per Pallet) | J10: 2026 | K10: 5 | L10: USD | M10: 262.00913 | N10: 1 | O10: =M10*N10 -> 262.00913 | P10: BSArgentina | R10: =+VLOOKUP(E10,'Selectable Table'!B:C,2,0) -> Storage | V10: Grand Total | W10: 1342483 | Y10: =SUM(Y4:Y9) -> 1342483 | Z10: =W10-Y10 -> 0
B11: 56021927PCR3011_Anc_Returns | C11: Janssen | D11: Argentina | E11: Total Storage | F11: 40700 | G11: Revenues - Third Parties | I11: Non-Drug Storage Ambient (per Pallet) | J11: 2026 | K11: 5 | L11: USD | M11: 181.94435 | N11: 1 | O11: =M11*N11 -> 181.94435 | P11: BSArgentina | R11: =+VLOOKUP(E11,'Selectable Table'!B:C,2,0) -> Storage
B12: 56021927PCR3011_Anc_Returns | C12: Janssen | D12: Argentina | E12: Total Storage | F12: 40700 | G12: Revenues - Third Parties | I12: Storage of Returns (per Pallet) | J12: 2026 | K12: 5 | L12: USD | M12: 87.336375 | N12: 1 | O12: =M12*N12 -> 87.336375 | P12: BSArgentina | R12: =+VLOOKUP(E12,'Selectable Table'!B:C,2,0) -> Storage
B13: CNTO1959UCO3001_Anc_Returns | C13: Janssen | D13: Argentina | E13: Total Storage | F13: 40700 | G13: Revenues - Third Parties | I13: Non-Drug Storage Ambient (per Pallet) | J13: 2026 | K13: 5 | L13: USD | M13: 1091.6661 | N13: 1 | O13: =M13*N13 -> 1091.6661 | P13: BSArgentina | R13: =+VLOOKUP(E13,'Selectable Table'!B:C,2,0) -> Storage | V13: Antes del ajuste:
B14: CNTO1959UCO3001_Anc_Returns | C14: Janssen | D14: Argentina | E14: Total Storage | F14: 40700 | G14: Revenues - Third Parties | I14: Storage of Returns (per Pallet) | J14: 2026 | K14: 5 | L14: USD | M14: 436.68187 | N14: 1 | O14: =M14*N14 -> 436.68187 | P14: BSArgentina | R14: =+VLOOKUP(E14,'Selectable Table'!B:C,2,0) -> Storage
B15: AC-055-315_anc_returns | C15: Janssen | D15: Argentina | E15: Total Storage | F15: 40700 | G15: Revenues - Third Parties | I15: Non-Drug Storage Ambient (per Pallet) | J15: 2026 | K15: 5 | L15: USD | M15: 181.94435 | N15: 1 | O15: =M15*N15 -> 181.94435 | P15: BSArgentina | R15: =+VLOOKUP(E15,'Selectable Table'!B:C,2,0) -> Storage
B16: AC-055-315_anc_returns | C16: Janssen | D16: Argentina | E16: Total Storage | F16: 40700 | G16: Revenues - Third Parties | I16: Storage Ambient (per Pallet) | J16: 2026 | K16: 5 | L16: USD | M16: 545.83305 | N16: 1 | O16: =M16*N16 -> 545.83305 | P16: BSArgentina | R16: =+VLOOKUP(E16,'Selectable Table'!B:C,2,0) -> Storage
B17: AC-055-315_anc_returns | C17: Janssen | D17: Argentina | E17: Total Storage | F17: 40700 | G17: Revenues - Third Parties | I17: Storage of Returns (per Pallet) | J17: 2026 | K17: 5 | L17: USD | M17: 611.35463 | N17: 1 | O17: =M17*N17 -> 611.35463 | P17: BSArgentina | R17: =+VLOOKUP(E17,'Selectable Table'!B:C,2,0) -> Storage
B18: 67652000PCR3002_anc_returns | C18: Janssen | D18: Argentina | E18: Total Freight | F18: 40700 | G18: Revenues - Third Parties | I18: Freight - Returns | J18: 2026 | K18: 5 | L18: USD | M18: 333.03 | N18: 1 | O18: =M18*N18 -> 333.03 | P18: BSArgentina | R18: =+VLOOKUP(E18,'Selectable Table'!B:C,2,0) -> Freight
B19: 67652000PCR3002_anc_returns | C19: Janssen | D19: Argentina | E19: Total Storage | F19: 40700 | G19: Revenues - Third Parties | I19: Storage of Returns (per Pallet) | J19: 2026 | K19: 5 | L19: USD | M19: 786.02738 | N19: 1 | O19: =M19*N19 -> 786.02738 | P19: BSArgentina | R19: =+VLOOKUP(E19,'Selectable Table'!B:C,2,0) -> Storage
B20: 73841937NSC3003_Anc_Returns | C20: Janssen | D20: Argentina | E20: Total Freight | F20: 40700 | G20: Revenues - Third Parties | I20: Freight - Returns | J20: 2026 | K20: 5 | L20: USD | M20: 752.04 | N20: 1 | O20: =M20*N20 -> 752.04 | P20: BSArgentina | R20: =+VLOOKUP(E20,'Selectable Table'!B:C,2,0) -> Freight
B21: 73841937NSC3003_Anc_Returns | C21: Janssen | D21: Argentina | E21: Total Storage | F21: 40700 | G21: Revenues - Third Parties | I21: Non-Drug Storage Ambient (per Pallet) | J21: 2026 | K21: 5 | L21: USD | M21: 181.94435 | N21: 1 | O21: =M21*N21 -> 181.94435 | P21: BSArgentina | R21: =+VLOOKUP(E21,'Selectable Table'!B:C,2,0) -> Storage
B22: 73841937NSC3003_Anc_Returns | C22: Janssen | D22: Argentina | E22: Total Return Drug | F22: 40700 | G22: Revenues - Third Parties | I22: Reconciliation of Returns (per Hour) | J22: 2026 | K22: 5 | L22: USD | M22: 50.944075 | N22: 1 | O22: =M22*N22 -> 50.944075 | P22: BSArgentina | R22: =+VLOOKUP(E22,'Selectable Table'!B:C,2,0) -> ReturnDrug
B23: 73841937NSC3003_Anc_Returns | C23: Janssen | D23: Argentina | E23: Total Return Drug | F23: 40700 | G23: Revenues - Third Parties | I23: Returns Receipt (per Receipt) | J23: 2026 | K23: 5 | L23: USD | M23: 133.72713 | N23: 1 | O23: =M23*N23 -> 133.72713 | P23: BSArgentina | R23: =+VLOOKUP(E23,'Selectable Table'!B:C,2,0) -> ReturnDrug
B24: 73841937NSC3003_Anc_Returns | C24: Janssen | D24: Argentina | E24: Total Storage | F24: 40700 | G24: Revenues - Third Parties | I24: Storage of Returns (per Pallet) | J24: 2026 | K24: 5 | L24: USD | M24: 611.35463 | N24: 1 | O24: =M24*N24 -> 611.35463 | P24: BSArgentina | R24: =+VLOOKUP(E24,'Selectable Table'!B:C,2,0) -> Storage
B25: CNTO1959PSA4002_Anc_Returns | C25: Janssen | D25: Argentina | E25: Total Freight | F25: 40700 | G25: Revenues - Third Parties | I25: Freight - Returns | J25: 2026 | K25: 5 | L25: USD | M25: 191.15 | N25: 1 | O25: =M25*N25 -> 191.15 | P25: BSArgentina | R25: =+VLOOKUP(E25,'Selectable Table'!B:C,2,0) -> Freight
... B434: PHRI.COLT-HF | C434: Site Management Organization Argentina SA | D434: Argentina | E434: Total Storage | F434: 40700 | G434: Revenues - Third Parties | I434: Storage of Labels Ambient (per Pallet) | J434: 2026 | K434: 5 | L434: USD | M434: 1011.84 | N434: 1 | O434: =M434*N434 -> 1011.84 | P434: BSArgentina | R434: =+VLOOKUP(E434,'Selectable Table'!B:C,2,0) -> Storage
B435: PHRI.COLT-HF | C435: Site Management Organization Argentina SA | D435: Argentina | E435: Total Return Drug | F435: 40700 | G435: Revenues - Third Parties | I435: Destruction (per Kg) | J435: 2026 | K435: 5 | L435: USD | M435: -106.65 | N435: 1 | O435: =M435*N435 -> -106.65 | P435: BSArgentina | R435: =+VLOOKUP(E435,'Selectable Table'!B:C,2,0) -> ReturnDrug | T435: CN NO TP
B436: PHRI.COLT-HF | C436: Site Management Organization Argentina SA | D436: Argentina | E436: Total Return Drug | F436: 40700 | G436: Revenues - Third Parties | I436: Destruction Setup Fee | J436: 2026 | K436: 5 | L436: USD | M436: -1360.1 | N436: 1 | O436: =M436*N436 -> -1360.1 | P436: BSArgentina | R436: =+VLOOKUP(E436,'Selectable Table'!B:C,2,0) -> ReturnDrug | T436: CN NO TP
B437: PHRI.COLT-HF | C437: Site Management Organization Argentina SA | D437: Argentina | E437: Total Storage | F437: 40700 | G437: Revenues - Third Parties | I437: Non-Drug Storage Ambient (per Shelf) | J437: 2026 | K437: 5 | L437: USD | M437: -95 | N437: 1 | O437: =M437*N437 -> -95 | P437: BSArgentina | R437: =+VLOOKUP(E437,'Selectable Table'!B:C,2,0) -> Storage | T437: CN NO TP
B438: PHRI.COLT-HF | C438: Site Management Organization Argentina SA | D438: Argentina | E438: Total Distribution | F438: 40700 | G438: Revenues - Third Parties | I438: Project Management Fee | J438: 2026 | K438: 5 | L438: USD | M438: -450 | N438: 1 | O438: =M438*N438 -> -450 | P438: BSArgentina | R438: =+VLOOKUP(E438,'Selectable Table'!B:C,2,0) -> Distribution | T438: CN NO TP
B439: PHRI.COLT-HF | C439: Site Management Organization Argentina SA | D439: Argentina | E439: Total Distribution | F439: 40700 | G439: Revenues - Third Parties | I439: Receipt of Labels (per Receipt_ID) | J439: 2026 | K439: 5 | L439: USD | M439: -296.4 | N439: 1 | O439: =M439*N439 -> -296.4 | P439: BSArgentina | R439: =+VLOOKUP(E439,'Selectable Table'!B:C,2,0) -> Distribution | T439: CN NO TP
B440: PHRI.COLT-HF | C440: Site Management Organization Argentina SA | D440: Argentina | E440: Total Storage | F440: 40700 | G440: Revenues - Third Parties | I440: Storage Ambient (per Pallet) | J440: 2026 | K440: 5 | L440: USD | M440: -3243.1 | N440: 1 | O440: =M440*N440 -> -3243.1 | P440: BSArgentina | R440: =+VLOOKUP(E440,'Selectable Table'!B:C,2,0) -> Storage | T440: CN NO TP
B441: PHRI.COLT-HF | C441: Site Management Organization Argentina SA | D441: Argentina | E441: Total Storage | F441: 40700 | G441: Revenues - Third Parties | I441: Storage of Labels Ambient (per Pallet) | J441: 2026 | K441: 5 | L441: USD | M441: -1349.12 | N441: 1 | O441: =M441*N441 -> -1349.12 | P441: BSArgentina | R441: =+VLOOKUP(E441,'Selectable Table'!B:C,2,0) -> Storage | T441: CN NO TP
B442: PHRI.COLT-HF | C442: Site Management Organization Argentina SA | D442: Argentina | E442: Total Return Drug | F442: 40700 | G442: Revenues - Third Parties | I442: Destruction (per Kg) | J442: 2026 | K442: 5 | L442: USD | M442: 106.65 | N442: 1 | O442: =M442*N442 -> 106.65 | P442: BSArgentina | R442: =+VLOOKUP(E442,'Selectable Table'!B:C,2,0) -> ReturnDrug | T442: RB NO TP
B443: PHRI.COLT-HF | C443: Site Management Organization Argentina SA | D443: Argentina | E443: Total Return Drug | F443: 40700 | G443: Revenues - Third Parties | I443: Destruction Setup Fee | J443: 2026 | K443: 5 | L443: USD | M443: 1360.1 | N443: 1 | O443: =M443*N443 -> 1360.1 | P443: BSArgentina | R443: =+VLOOKUP(E443,'Selectable Table'!B:C,2,0) -> ReturnDrug | T443: RB NO TP
B444: PHRI.COLT-HF | C444: Site Management Organization Argentina SA | D444: Argentina | E444: Total Storage | F444: 40700 | G444: Revenues - Third Parties | I444: Non-Drug Storage Ambient (per Shelf) | J444: 2026 | K444: 5 | L444: USD | M444: 95 | N444: 1 | O444: =M444*N444 -> 95 | P444: BSArgentina | R444: =+VLOOKUP(E444,'Selectable Table'!B:C,2,0) -> Storage | T444: RB NO TP
B445: PHRI.COLT-HF | C445: Site Management Organization Argentina SA | D445: Argentina | E445: Total Distribution | F445: 40700 | G445: Revenues - Third Parties | I445: Project Management Fee | J445: 2026 | K445: 5 | L445: USD | M445: 450 | N445: 1 | O445: =M445*N445 -> 450 | P445: BSArgentina | R445: =+VLOOKUP(E445,'Selectable Table'!B:C,2,0) -> Distribution | T445: RB NO TP
B446: PHRI.COLT-HF | C446: Site Management Organization Argentina SA | D446: Argentina | E446: Total Storage | F446: 40700 | G446: Revenues - Third Parties | I446: Storage Ambient (per Pallet) | J446: 2026 | K446: 5 | L446: USD | M446: 3243.1 | N446: 1 | O446: =M446*N446 -> 3243.1 | P446: BSArgentina | R446: =+VLOOKUP(E446,'Selectable Table'!B:C,2,0) -> Storage | T446: RB NO TP
... B488: MK-2400-001 (Local) | C488: Merck Sharp and Dohme LLC | D488: Argentina | E488: Total Storage | F488: 40700 | G488: Revenues - Third Parties | I488: Storage Ambient (per Pallet) | J488: 2026 | K488: 5 | L488: USD | M488: 286.89 | N488: 1 | O488: =M488*N488 -> 286.89 | P488: BSArgentina | R488: =+VLOOKUP(E488,'Selectable Table'!B:C,2,0) -> Storage | T488: Ajuste manual
B489: I8F-MC-GPJA (CAM) | C489: Eli Lilly & Co. | D489: Argentina | E489: Total Freight | F489: 40700 | G489: Revenues - Third Parties | I489: Annual Rebate | J489: 2026 | K489: 5 | L489: USD | M489: 0 | N489: 1 | O489: =M489*N489 -> 0 | P489: BSArgentina | R489: =+VLOOKUP(E489,'Selectable Table'!B:C,2,0) -> Freight
...

Sheet Bra TP
A1: Vacio | B1: Protocol | C1: Element 4 short name | D1: Allentown / Argentina | E1: Custom 2 | H1: Vacio | I1: Line description | J1: YYYY | K1: MM | L1: CURRENCY | M1: 40 % (sin hadling) | O1: 40 % (sin hadling) | P1: Vacio | Q1: Not Applicable (solo para Allentown) | R1: Vacio | S1: Vacio | Y1: LocalAdj- Duties | Z1: ICO+NONICO
A2: grpcode | B2: el4 | C2: el4_name | D2: el4_sname | E2: name | F2: el2 | G2: el2_name | H2: el3 | I2: el3_name | J2: yr | K2: period | L2: curcode | M2: LOC AMT | N2: Rate | O2: USD AMT | P2: cmpcode | Q2: Discount Flag | R2: _ | S2: x
B3: EMN30-64007957MMY3003 - Azidus | C3: Azidus Brasil Pesquisa Científica | D3: Brazil | E3: Duties | I3: PTC Duties | M3: -11829.375 | O3: -11829.375 | P3: BSBRAZILTP | Q3: Not Applicable
B4: Bayer - Importer of Record Services | C4: Bayer AG (No consolidate) | D4: Brazil | E4: Duties | I4: PTC Duties | M4: -51624.855 | O4: -51624.855 | P4: BSBRAZILTP | Q4: Not Applicable
B5: J3R-MC-YDAL (CAM) | C5: Eli Lilly & Co. | D5: Brazil | E5: Duties | I5: PTC Duties | M5: -3111.4067 | O5: -3111.4067 | P5: BSBRAZILTP | Q5: Not Applicable
B6: J3R-MC-YDAO (CAM) | C6: Eli Lilly & Co. | D6: Brazil | E6: Duties | I6: PTC Duties | M6: -2251.0131 | O6: -2251.0131 | P6: BSBRAZILTP | Q6: Not Applicable
B7: Lilly Admin and one-time costs | C7: Eli Lilly & Co. | D7: Brazil | E7: Duties | I7: PTC Duties | M7: -411.37841 | O7: -411.37841 | P7: BSBRAZILTP | Q7: Not Applicable
B8: 42756493BLC3001 | C8: Janssen | D8: Brazil | E8: Duties | I8: PTC Duties | M8: -4020.2542 | O8: -4020.2542 | P8: BSBRAZILTP | Q8: Not Applicable
B9: 39039039THR3001 | C9: Janssen | D9: Brazil | E9: Duties | I9: PTC Duties | M9: -167.03421 | O9: -167.03421 | P9: BSBRAZILTP | Q9: Not Applicable
B10: J2G-MC-JZJB | C10: Eli Lilly & Co. | D10: Brazil | E10: Duties | I10: PTC Duties | M10: -71332.26 | O10: -71332.26 | P10: BSBRAZILTP | Q10: Not Applicable
B11: I8F-MC-GPGN | C11: Eli Lilly & Co. | D11: Brazil | E11: Duties | I11: PTC Duties | M11: -4990.8416 | O11: -4990.8416 | P11: BSBRAZILTP | Q11: Not Applicable
B12: 67652000PCR3002 | C12: Janssen | D12: Brazil | E12: Duties | I12: PTC Duties | M12: -978.88072 | O12: -978.88072 | P12: BSBRAZILTP | Q12: Not Applicable
B13: J2G-MC-JZJX | C13: Eli Lilly & Co. | D13: Brazil | E13: Duties | I13: PTC Duties | M13: -20455.044 | O13: -20455.044 | P13: BSBRAZILTP | Q13: Not Applicable
B14: I8F-MC-GPI1 | C14: Eli Lilly & Co. | D14: Brazil | E14: Duties | I14: PTC Duties | M14: -1941.8632 | O14: -1941.8632 | P14: BSBRAZILTP | Q14: Not Applicable
... B42: D926NC00001 | C42: Astra Zeneca | D42: Brazil | E42: Duties | I42: PTC Duties | M42: -1423.6512 | O42: -1423.6512 | P42: BSBRAZILTP | Q42: Not Applicable
B43: 20190360 | C43: Amgen, Inc. | D43: Brazil | E43: Duties | I43: PTC Duties | M43: -1954.3925 | O43: -1954.3925 | P43: BSBRAZILTP | Q43: Not Applicable
B44: D7020C00001 | C44: MedImmune Inc | D44: Brazil | E44: Duties | I44: PTC Duties | M44: -2074.644 | O44: -2074.644 | P44: BSBRAZILTP | Q44: Not Applicable
B45: D3466C00001 | C45: Astra Zeneca | D45: Brazil | E45: Duties | I45: PTC Duties | M45: -951.91133 | O45: -951.91133 | P45: BSBRAZILTP | Q45: Not Applicable
B46: Temperature Monitor-Global Pooling | C46: Astra Zeneca | D46: Brazil | E46: Duties | I46: PTC Duties | M46: -3786.9723 | O46: -3786.9723 | P46: BSBRAZILTP | Q46: Not Applicable
B47: D8535C00001 | C47: Astra Zeneca | D47: Brazil | E47: Duties | I47: PTC Duties | M47: -13046.734 | O47: -13046.734 | P47: BSBRAZILTP | Q47: Not Applicable
B48: D926QC00001 | C48: Astra Zeneca | D48: Brazil | E48: Duties | I48: PTC Duties | M48: -304.36061 | O48: -304.36061 | P48: BSBRAZILTP | Q48: Not Applicable
B49: 20200041 | C49: Amgen, Inc. | D49: Brazil | E49: Duties | I49: PTC Duties | M49: -2020.4439 | O49: -2020.4439 | P49: BSBRAZILTP | Q49: Not Applicable
B50: D781PC00001 | C50: Astra Zeneca | D50: Brazil | E50: Duties | I50: PTC Duties | M50: -3326.7951 | O50: -3326.7951 | P50: BSBRAZILTP | Q50: Not Applicable
B51: 20230167 | C51: Amgen, Inc. | D51: Brazil | E51: Duties | I51: PTC Duties | M51: -17933.864 | O51: -17933.864 | P51: BSBRAZILTP | Q51: Not Applicable
B52: D516NC00001 | C52: Astra Zeneca | D52: Brazil | E52: Duties | I52: PTC Duties | M52: -1378.2534 | O52: -1378.2534 | P52: BSBRAZILTP | Q52: Not Applicable
B53: D7029C00001 | C53: Astra Zeneca | D53: Brazil | E53: Duties | I53: PTC Duties | M53: -282.23355 | O53: -282.23355 | P53: BSBRAZILTP | Q53: Not Applicable
B54: 20240178 | C54: Amgen, Inc. | D54: Brazil | E54: Duties | I54: PTC Duties | M54: -1592.6469 | O54: -1592.6469 | P54: BSBRAZILTP | Q54: Not Applicable
B55: 20220196 | C55: Amgen, Inc. | D55: Brazil | E55: Duties | I55: PTC Duties | M55: -57156.5 | O55: -57156.5 | P55: BSBRAZILTP | Q55: Not Applicable
B56: 20240236 | C56: Amgen, Inc. | D56: Brazil | E56: Duties | I56: PTC Duties | M56: -101341.14 | O56: -101341.14 | P56: BSBRAZILTP | Q56: Not Applicable
B57: 20240202 | C57: Amgen, Inc. | D57: Brazil | E57: Duties | I57: PTC Duties | M57: -121293.41 | O57: -121293.41 | P57: BSBRAZILTP | Q57: Not Applicable
B58: 20240113 | C58: Amgen, Inc. | D58: Brazil | E58: Duties | I58: PTC Duties | M58: -4109.7782 | O58: -4109.7782 | P58: BSBRAZILTP | Q58: Not Applicable
B59: GRN163LMYF3001 | C59: Geron Corporation | D59: Brazil | E59: Duties | I59: PTC Duties | M59: -10945.41 | O59: -10945.41 | P59: BSBRAZILTP | Q59: Not Applicable
B60: KRT-232-101 | C60: Kartos Therapeutics Inc | D60: Brazil | E60: Duties | I60: PTC Duties | M60: -193.8339 | O60: -193.8339 | P60: BSBRAZILTP | Q60: Not Applicable
B61: LP352-301 | C61: Longboard Pharmaceuticals | D61: Brazil | E61: Duties | I61: PTC Duties | M61: -3539.7063 | O61: -3539.7063 | P61: BSBRAZILTP | Q61: Not Applicable
B62: LP352-302 | C62: Longboard Pharmaceuticals | D62: Brazil | E62: Duties | I62: PTC Duties | M62: -3245.5531 | O62: -3245.5531 | P62: BSBRAZILTP | Q62: Not Applicable
B63: D9640C00003 | C63: MedImmune Inc | D63: Brazil | E63: Duties | I63: PTC Duties | M63: -2324.5528 | O63: -2324.5528 | P63: BSBRAZILTP | Q63: Not Applicable
B64: V940-011 (Local) | C64: Merck Sharp and Dohme LLC | D64: Brazil | E64: Duties | I64: PTC Duties | M64: -251.67887 | O64: -251.67887 | P64: BSBRAZILTP | Q64: Not Applicable
B65: MK-7962-038 (Local) | C65: Merck Sharp and Dohme LLC | D65: Brazil | E65: Duties | I65: PTC Duties | M65: -633.92047 | O65: -633.92047 | P65: BSBRAZILTP | Q65: Not Applicable
B66: MK-8748-003 (Local) | C66: Merck Sharp and Dohme LLC | D66: Brazil | E66: Duties | I66: PTC Duties | M66: -1026.5794 | O66: -1026.5794 | P66: BSBRAZILTP | Q66: Not Applicable
B67: BGB-43395-101 | C67: BeOne | D67: Brazil | E67: Freight | I67: Freight - Returns | M67: -752.97211 | O67: -752.97211 | P67: BSBRAZILTP | Q67: Not Applicable
...

Sheet Bra
A1: Vacio | B1: Protocol | C1: Element 4 short name | D1: Allentown / Argentina | E1: Custom 2 | H1: Vacio | I1: Line description | J1: YYYY | K1: MM | L1: CURRENCY | M1: 40 % (sin hadling) | O1: 40 % (sin hadling) | P1: Vacio | Q1: Not Applicable (solo para Allentown) | R1: Vacio | S1: Vacio | Y1: LocalAdj- Duties | Z1: ICO+NONICO
A2: grpcode | B2: el4 | C2: el4_name | D2: el4_sname | E2: name | F2: el2 | G2: el2_name | H2: el3 | I2: el3_name | J2: yr | K2: period | L2: curcode | M2: LOC AMT | N2: Rate | O2: USD AMT | P2: cmpcode | Q2: Discount Flag | R2: _ | S2: x
B3: Transfer Pricing | C3: Allentown | D3: Allentown | E3: Distribution | F3: 40700 | G3: Revenues - Third Parties | I3: Transfer Pricing | J3: 2026 | K3: 5 | L3: USD | M3: 1115806.2 | O3: 1115806.2 | P3: BSBrazilUSD | Q3: Not Applicable
B4: Transfer Pricing | C4: Allentown | D4: Allentown | E4: Duties | F4: 40700 | G4: Revenues - Third Parties | I4: Transfer Pricing | J4: 2026 | K4: 5 | L4: USD | M4: 1529489.2 | O4: 1529489.2 | P4: BSBrazilUSD | Q4: Not Applicable
B5: Transfer Pricing | C5: Allentown | D5: Allentown | E5: Freight | F5: 40700 | G5: Revenues - Third Parties | I5: Transfer Pricing | J5: 2026 | K5: 5 | L5: USD | M5: 1727743 | O5: 1727743 | P5: BSBrazilUSD | Q5: Not Applicable
B6: Transfer Pricing | C6: Allentown | D6: Allentown | E6: Packaging | F6: 40700 | G6: Revenues - Third Parties | I6: Transfer Pricing | J6: 2026 | K6: 5 | L6: USD | M6: 15291.33 | O6: 15291.33 | P6: BSBrazilUSD | Q6: Not Applicable
B7: Transfer Pricing | C7: Allentown | D7: Allentown | E7: Returns and Destructions | F7: 40700 | G7: Revenues - Third Parties | I7: Transfer Pricing | J7: 2026 | K7: 5 | L7: USD | M7: 97572.4 | O7: 97572.4 | P7: BSBrazilUSD | Q7: Not Applicable | AD7: 615737
B8: Transfer Pricing | C8: Allentown | D8: Allentown | E8: Storage | F8: 40700 | G8: Revenues - Third Parties | I8: Transfer Pricing | J8: 2026 | K8: 5 | L8: USD | M8: 533585.46 | O8: 533585.46 | P8: BSBrazilUSD | Q8: Not Applicable | AD8: 626211
B9: BGB-43395-101 | C9: BeOne | D9: Brazil | E9: Freight | I9: Freight - Returns | K9: 5 | M9: 1755.0773 | O9: 1755.0773 | P9: BSBrazilUSD | AD9: =+AD8+AD7 -> 1241948
B10: BGB-43395-101 | C10: BeOne | D10: Brazil | E10: Freight | I10: Freight - Shipments | K10: 5 | M10: 2814.7656 | O10: 2814.7656 | P10: BSBrazilUSD
B11: BGB-43395-101 | C11: BeOne | D11: Brazil | E11: Distribution | I11: Insulated shipper - Credo S22 - 12L (Leasing) | K11: 5 | M11: 174.59476 | O11: 174.59476 | P11: BSBrazilUSD
B12: BGB-43395-101 | C12: BeOne | D12: Brazil | E12: Distribution | I12: Pick and Pack (Controlled Ambient) | K12: 5 | M12: 415.52753 | O12: 415.52753 | P12: BSBrazilUSD
B13: BGB-43395-101 | C13: BeOne | D13: Brazil | E13: Distribution | I13: Project Management Fee | K13: 5 | M13: 986.90039 | O13: 986.90039 | P13: BSBrazilUSD
B14: BGB-43395-101 | C14: BeOne | D14: Brazil | E14: Returns and Destructions | I14: Reconciliation of Returns (per Hour) | K14: 5 | M14: 277.03169 | O14: 277.03169 | P14: BSBrazilUSD
B15: BGB-43395-101 | C15: BeOne | D15: Brazil | E15: Returns and Destructions | I15: Returns Receipt (per Receipt) | K15: 5 | M15: 692.57922 | O15: 692.57922 | P15: BSBrazilUSD
B16: BGB-43395-101 | C16: BeOne | D16: Brazil | E16: Storage | I16: Storage Ambient (per Shelf) | K16: 5 | M16: 2960.9112 | O16: 2960.9112 | P16: BSBrazilUSD
B17: BGB-43395-101 | C17: BeOne | D17: Brazil | E17: Storage | I17: Storage of Returns (per Pallet) | K17: 5 | M17: 1113.8066 | O17: 1113.8066 | P17: BSBrazilUSD
B18: BGB-43395-101 | C18: BeOne | D18: Brazil | E18: Distribution | I18: Temperature Monitoring Device (Ambient) | K18: 5 | M18: 77.597672 | O18: 77.597672 | P18: BSBrazilUSD
B19: BGB-Retain sample storage | C19: BeOne | D19: Brazil | E19: Storage | I19: Storage Ambient (per Shelf) | K19: 5 | M19: 528.73414 | O19: 528.73414 | P19: BSBrazilUSD
B20: BGB-58067-101 | C20: BeOne | D20: Brazil | E20: Distribution | I20: Project Management Fee | K20: 5 | M20: 888.21335 | O20: 888.21335 | P20: BSBrazilUSD
B21: BGB-58067-101 | C21: BeOne | D21: Brazil | E21: Storage | I21: Storage Ambient (per Shelf) | K21: 5 | M21: 317.24048 | O21: 317.24048 | P21: BSBrazilUSD
B22: BGB-58067-101 | C22: BeOne | D22: Brazil | E22: Storage | I22: Storage Refrigerated (per Shelf) | K22: 5 | M22: 444.10668 | O22: 444.10668 | P22: BSBrazilUSD
B23: D3251C00014 Returns and Destruction | C23: Astra Zeneca | D23: Brazil | E23: Storage | I23: Storage of Returns (per Pallet) | M23: 472.11275 | O23: 472.11275 | P23: BSBrazilUSD
B24: D9185C00001 Returns and Destruction | C24: Astra Zeneca | D24: Brazil | E24: Freight | I24: Freight - Returns | M24: 719.93938 | O24: 719.93938 | P24: BSBrazilUSD
B25: D9185C00001 Returns and Destruction | C25: Astra Zeneca | D25: Brazil | E25: Storage | I25: Storage of Returns (per Pallet) | M25: 343.01 | O25: 343.01 | P25: BSBrazilUSD
B26: D5244C00001 Returns and Destruction | C26: Astra Zeneca | D26: Brazil | E26: Storage | I26: Storage of Returns (per Pallet) | M26: 366.81992 | O26: 366.81992 | P26: BSBrazilUSD
B27: D9180C00012 Returns and Destruction | C27: Astra Zeneca | D27: Brazil | E27: Freight | I27: Freight - Returns | M27: 122.72101 | O27: 122.72101 | P27: BSBrazilUSD
B28: D9180C00012 Returns and Destruction | C28: Astra Zeneca | D28: Brazil | E28: Returns and Destructions | I28: Returns Receipt (per Receipt) | M28: 195.91208 | O28: 195.91208 | P28: BSBrazilUSD
B29: D9180C00012 Returns and Destruction | C29: Astra Zeneca | D29: Brazil | E29: Storage | I29: Storage of Returns (per Pallet) | M29: 240.70094 | O29: 240.70094 | P29: BSBrazilUSD
B30: D6972C00003 Returns and Destruction | C30: Astra Zeneca | D30: Brazil | E30: Storage | I30: Storage of Returns (per Pallet) | M30: 240.70094 | O30: 240.70094 | P30: BSBrazilUSD
B31: D6402C00012 Returns and Destruction | C31: Astra Zeneca | D31: Brazil | E31: Returns and Destructions | I31: Returns Receipt (per Receipt) | M31: 181.85976 | O31: 181.85976 | P31: BSBrazilUSD
B32: D6402C00012 Returns and Destruction | C32: Astra Zeneca | D32: Brazil | E32: Storage | I32: Storage of Returns (per Pallet) | M32: 183.40996 | O32: 183.40996 | P32: BSBrazilUSD
B33: D9180C00008 Returns and Destruction | C33: Astra Zeneca | D33: Brazil | E33: Storage | I33: Storage of Returns (per Pallet) | M33: 453.97282 | O33: 453.97282 | P33: BSBrazilUSD
B34: D9180C00004 Returns and Destruction | C34: Astra Zeneca | D34: Brazil | E34: Storage | I34: Storage of Returns (per Pallet) | M34: 366.81992 | O34: 366.81992 | P34: BSBrazilUSD
... B551: D926NC00001 | C551: Astra Zeneca | D551: Brazil | E551: Duties | I551: PTC Duties | M551: -2135.4768 | O551: -2135.4768 | P551: BSBrazilUSD
B552: 20190360 | C552: Amgen, Inc. | D552: Brazil | E552: Duties | I552: PTC Duties | M552: -2931.5887 | O552: -2931.5887 | P552: BSBrazilUSD
B553: D7020C00001 | C553: MedImmune Inc | D553: Brazil | E553: Duties | I553: PTC Duties | M553: -3111.9661 | O553: -3111.9661 | P553: BSBrazilUSD
B554: D3466C00001 | C554: Astra Zeneca | D554: Brazil | E554: Duties | I554: PTC Duties | M554: -1427.867 | O554: -1427.867 | P554: BSBrazilUSD
B555: Temperature Monitor-Global Pooling | C555: Astra Zeneca | D555: Brazil | E555: Duties | I555: PTC Duties | M555: -5680.4585 | O555: -5680.4585 | P555: BSBrazilUSD
B556: D8535C00001 | C556: Astra Zeneca | D556: Brazil | E556: Duties | I556: PTC Duties | M556: -19570.1 | O556: -19570.1 | P556: BSBrazilUSD
...

Sheet Mex 
A1: Vacio | B1: Protocol | C1: Element 4 short name | D1: Allentown / Argentina | E1: Custom 2 | H1: Vacio | I1: Line description | J1: YYYY | K1: MM | L1: CURRENCY | M1: 40 % (sin hadling) | O1: 40 % (sin hadling) | P1: Vacio | Q1: Not Applicable (solo para Allentown) | R1: Vacio | S1: Vacio
A2: grpcode | B2: el4 | C2: el4_name | D2: el4_sname | E2: name | F2: el2 | G2: el2_name | H2: el3 | I2: el3_name | J2: yr | K2: period | L2: curcode | M2: LOC AMT | N2: Rate | O2: USD AMT | P2: cmpcode | Q2: Discount Flag | R2: _ | S2: x
B3: Transfer Pricing | C3: Allentown | D3: Allentown | E3: Distribution | F3: 40700 | G3: Revenues - Third Parties | I3: Transfer Pricing | J3: 2026 | K3: 5 | L3: USD | M3: 173964.22 | O3: 173964.22 | P3: BSMexico | Q3: Not Applicable
B4: Transfer Pricing | C4: Allentown | D4: Allentown | E4: Duties | F4: 40700 | G4: Revenues - Third Parties | I4: Transfer Pricing | J4: 2026 | K4: 5 | L4: USD | M4: 12575.77 | O4: 12575.77 | P4: BSMexico | Q4: Not Applicable
B5: Transfer Pricing | C5: Allentown | D5: Allentown | E5: Freight | F5: 40700 | G5: Revenues - Third Parties | I5: Transfer Pricing | J5: 2026 | K5: 5 | L5: USD | M5: 88926.07 | O5: 88926.07 | P5: BSMexico | Q5: Not Applicable
B6: Transfer Pricing | C6: Allentown | D6: Allentown | E6: Packaging | F6: 40700 | G6: Revenues - Third Parties | I6: Transfer Pricing | J6: 2026 | K6: 5 | L6: USD | M6: 69.77 | O6: 69.77 | P6: BSMexico | Q6: Not Applicable
B7: Transfer Pricing | C7: Allentown | D7: Allentown | E7: Returns and Destructions | F7: 40700 | G7: Revenues - Third Parties | I7: Transfer Pricing | J7: 2026 | K7: 5 | L7: USD | M7: 14716.71 | O7: 14716.71 | P7: BSMexico | Q7: Not Applicable
B8: Transfer Pricing | C8: Allentown | D8: Allentown | E8: Storage | F8: 40700 | G8: Revenues - Third Parties | I8: Transfer Pricing | J8: 2026 | K8: 5 | L8: USD | M8: 115435.91 | O8: 115435.91 | P8: BSMexico | Q8: Not Applicable
B9: 20307 | C9: Bayer AG (No consolidate) | D9: Mexico | E9: Storage | I9: Storage Samples (per Shelf) | J9: 2026 | K9: 5 | L9: USD | M9: 201.26 | O9: 201.26 | P9: BSMexico
B10: IMP21500 | C10: Bayer AG (No consolidate) | D10: Mexico | E10: Distribution | I10: Project Management Fee | J10: 2026 | K10: 5 | L10: USD | M10: 385.4 | O10: 385.4 | P10: BSMexico
B11: IMP21500 | C11: Bayer AG (No consolidate) | D11: Mexico | E11: Storage | I11: Storage Samples (per Shelf) | J11: 2026 | K11: 5 | L11: USD | M11: 201.26 | O11: 201.26 | P11: BSMexico
B12: IMP22518 | C12: Bayer AG (No consolidate) | D12: Mexico | E12: Storage | I12: Storage Samples (per Shelf) | J12: 2026 | K12: 5 | L12: USD | M12: 201.26 | O12: 201.26 | P12: BSMexico
B13: IMP22518 | C13: Bayer AG (No consolidate) | D13: Mexico | E13: Returns and Destructions | I13: Destruction (per Kg) | J13: 2026 | K13: 5 | L13: USD | M13: 55.02 | O13: 55.02 | P13: BSMexico
B14: IMP22518 | C14: Bayer AG (No consolidate) | D14: Mexico | E14: Returns and Destructions | I14: Destruction Setup Fee | J14: 2026 | K14: 5 | L14: USD | M14: 384.22 | O14: 384.22 | P14: BSMexico
B15: IMP22518 | C15: Bayer AG (No consolidate) | D15: Mexico | E15: Distribution | I15: Project Management Fee | J15: 2026 | K15: 5 | L15: USD | M15: 469.16 | O15: 469.16 | P15: BSMexico
B16: IMP22518 | C16: Bayer AG (No consolidate) | D16: Mexico | E16: Storage | I16: Storage Ambient (per Shelf) | J16: 2026 | K16: 5 | L16: USD | M16: 142.3 | O16: 142.3 | P16: BSMexico
B17: IMP22518 | C17: Bayer AG (No consolidate) | D17: Mexico | E17: Storage | I17: Storage of Labels Ambient (per Shelf) | J17: 2026 | K17: 5 | L17: USD | M17: 71.15 | O17: 71.15 | P17: BSMexico
B18: Lilly Admin and one-time costs | C18: Eli Lilly & Co. | D18: Mexico | E18: Distribution | I18: Administrative fee | J18: 2026 | K18: 5 | L18: USD | M18: 12264.781 | O18: 12264.781 | P18: BSMexico
B19: Lilly Admin and one-time costs | C19: Eli Lilly & Co. | D19: Mexico | E19: Storage | I19: Non-Drug Storage Ambient (per Pallet) | J19: 2026 | K19: 5 | L19: USD | M19: 6878.1354 | O19: 6878.1354 | P19: BSMexico
B20: Lilly Admin and one-time costs | C20: Eli Lilly & Co. | D20: Mexico | E20: Distribution | I20: Receipt fee Ancillaries (per Receipt_ID) | J20: 2026 | K20: 5 | L20: USD | M20: 98.1212 | O20: 98.1212 | P20: BSMexico
B21: Lilly Admin and one-time costs | C21: Eli Lilly & Co. | D21: Mexico | E21: Storage | I21: Storage Ambient (per Shelf) | J21: 2026 | K21: 5 | L21: USD | M21: 14258.283 | O21: 14258.283 | P21: BSMexico
... B455: Others | C455: Others | D455: Mexico | E455: Distribution | I455: Others | J455: 2026 | K455: 5 | L455: USD | M455: 355966.5 | O455: 355966.5 | P455: BSMexico
B456: Others | C456: Others | D456: Mexico | E456: Duties | I456: Others | J456: 2026 | K456: 5 | L456: USD | M456: 116128.3 | O456: =116128.3227405+K472 -> 116128.3 | P456: BSMexico
B457: Others | C457: Others | D457: Mexico | E457: Freight | I457: Others | J457: 2026 | K457: 5 | L457: USD | M457: 437311.7 | O457: 437311.7 | P457: BSMexico
B458: Others | C458: Others | D458: Mexico | E458: Packaging | I458: Others | J458: 2026 | K458: 5 | L458: USD | M458: 0.23 | O458: 0.23 | P458: BSMexico
B459: Others | C459: Others | D459: Mexico | E459: Returns and Destructions | I459: Others | J459: 2026 | K459: 5 | L459: USD | M459: 49455.172 | O459: 49455.172 | P459: BSMexico
B460: Others | C460: Others | D460: Mexico | E460: ClinicalSvcsOther | I460: Others | J460: 2026 | K460: 5 | L460: USD | M460: 0 | O460: 0 | P460: BSMexico
M461: =SUM(M2:M460) -> 1499254 | N461: =SUM(N2:N460) -> 0 | O461: =SUM(O2:O460) -> 1499254
G466: Row Labels | H466: Sum of USD AMT
G467: ClinicalSvcsOther | H467: 0 | I467: 70 | J467: Packaging | K467: =+I467-GETPIVOTDATA("USD AMT",$G$466,"name","Packaging") -> 0
G468: Comparator | H468: 64909 | I468: 264052 | J468: Storage | K468: =+I468-GETPIVOTDATA("USD AMT",$G$466,"name","Storage") -> 0
G469: Distribution | H469: 306865 | I469: 306865 | J469: Distributing | K469: =+I469-GETPIVOTDATA("USD AMT",$G$466,"name","Distribution") -> 0
G470: Duties | H470: 74462.023 | I470: 733893 | J470: Freight | K470: =+I470-GETPIVOTDATA("USD AMT",$G$466,"name","Freight") -> 0
G471: Freight | H471: 733893 | I471: 55003 | J471: ReturnDrug | K471: =+I471-GETPIVOTDATA("USD AMT",$G$466,"name","Returns and Destructions") -> 0
G472: Packaging | H472: 70 | I472: 74462 | J472: BSDDuty | K472: =+I472-GETPIVOTDATA("USD AMT",$G$466,"name","Duties") -> -0.022674
G473: Returns and Destructions | H473: 55003 | I473: 0 | J473: ClinicalSvcsOther | K473: =+I473-GETPIVOTDATA("USD AMT",$G$466,"name","ClinicalSvcsOther") -> 0
G474: Storage | H474: 264052 | I474: 64909 | J474: Comparator | K474: =+I474-GETPIVOTDATA("USD AMT",$G$466,"name","Comparator") -> 0
G475: Grand Total | H475: 1499254 | J475: CAM

Sheet Arg (2)
A1: BuscarV de selectable table | B1: FB Invoice | C1: Fisher reference | D1: Protocol | E1: Año | F1: Mes del año en numero | G1: Category en FB BuscarV de selectable table | H1: Service | I1: Invoiced | J1: currency | K1: convertir el valor a BS USD RATE | L1: Site | M1: Solo PO | N1: blank | O1: Sponsor tal cual FB | P1: mismo columna K | Q1: fecha emision de facturacion | W1: Ex. Rates | X1: BS
A2: CUSTOMER | B2: INVOICE_. | C2: FISHER_JOB | D2: PROTOCOL | E2: yr | F2: period | G2: PRODUCT | H2: SUB-PRODUCT | I2: DocValue | J2: DOC_CURRENCY | K2: USD Value | L2: FISHER_LOC | M2: PO. | N2: doccode | O2: el4_name | P2: Home Currency | Q2: docdate | R2: ref1 | S2: el2 | T2: el2_name | U2: el3 | W2: USD | X2: 1
A3: =+VLOOKUP(O3,'Selectable Table'!$D$2:$E$1048576,2,0) -> J & J | B3: 30723 | C3: Local Trials | D3: Materiales pool Janssen | E3: 2025 | F3: 6 | G3: =+VLOOKUP(H3,Chi!#REF!,3,0) -> #REF! | H3: Non-Drug Storage Ambient (per Pallet) | I3: 1527.5899 | J3: USD | K3: =+VLOOKUP(J3,$W$2:$X$3,2,0)*I3 -> 1527.5899 | L3: Argentina | M3: Local Trials | O3: Janssen | P3: =K3 -> 1527.5899 | Q3: 45831 | S3: 40700 | T3: Revenues - Third Parties | W3: USD | X3: 1
A4: =+VLOOKUP(O4,'Selectable Table'!$D$2:$E$1048576,2,0) -> J & J | B4: 30723 | C4: Local Trials | D4: Materiales pool Janssen | E4: 2025 | F4: 6 | G4: =+VLOOKUP(H4,Chi!#REF!,3,0) -> #REF! | H4: Receipt fee Ancillaries (per Receipt_ID) | I4: 240.0519 | J4: USD | K4: =+VLOOKUP(J4,$W$2:$X$3,2,0)*I4 -> 240.0519 | L4: Argentina | M4: Local Trials | O4: Janssen | P4: =K4 -> 240.0519 | Q4: 45831 | S4: 40700 | T4: Revenues - Third Parties | W4: EUR | X4: 1.1609
A5: =+VLOOKUP(O5,'Selectable Table'!$D$2:$E$1048576,2,0) -> J & J | B5: 30724 | C5: Local Trial | D5: 64091742PCR3001_anc_returns | E5: 2025 | F5: 6 | G5: =+VLOOKUP(H5,Chi!#REF!,3,0) -> #REF! | H5: Storage of Returns (per Pallet) | I5: 209.50545 | J5: USD | K5: =+VLOOKUP(J5,$W$2:$X$3,2,0)*I5 -> 209.50545 | L5: Argentina | M5: Local Trial | O5: Janssen | P5: =K5 -> 209.50545 | Q5: 45831 | S5: 40700 | T5: Revenues - Third Parties | W5: CHF | X5: 1.2418
A6: =+VLOOKUP(O6,'Selectable Table'!$D$2:$E$1048576,2,0) -> J & J | B6: 30725 | C6: Local Trials | D6: 56021927PCR3011_Anc_Returns | E6: 2025 | F6: 6 | G6: =+VLOOKUP(H6,Chi!#REF!,3,0) -> #REF! | H6: Non-Drug Storage Ambient (per Pallet) | I6: 218.22713 | J6: USD | K6: =+VLOOKUP(J6,$W$2:$X$3,2,0)*I6 -> 218.22713 | L6: Argentina | M6: Local Trials | O6: Janssen | P6: =K6 -> 218.22713 | Q6: 45831 | S6: 40700 | T6: Revenues - Third Parties | W6: CLP | X6: 0.00107
A7: =+VLOOKUP(O7,'Selectable Table'!$D$2:$E$1048576,2,0) -> J & J | B7: 30725 | C7: Local Trials | D7: 56021927PCR3011_Anc_Returns | E7: 2025 | F7: 6 | G7: =+VLOOKUP(H7,Chi!#REF!,3,0) -> #REF! | H7: Storage of Returns (per Pallet) | I7: 104.75272 | J7: USD | K7: =+VLOOKUP(J7,$W$2:$X$3,2,0)*I7 -> 104.75272 | L7: Argentina | M7: Local Trials | O7: Janssen | P7: =K7 -> 104.75272 | Q7: 45831 | S7: 40700 | T7: Revenues - Third Parties | W7: GBP | X7: 1.3615
A8: =+VLOOKUP(O8,'Selectable Table'!$D$2:$E$1048576,2,0) -> J & J | B8: 30726 | C8: Local Trials | D8: CNTO1959UCO3001_Anc_Returns | E8: 2025 | F8: 6 | G8: =+VLOOKUP(H8,Chi!#REF!,3,0) -> #REF! | H8: Non-Drug Storage Ambient (per Pallet) | I8: 1309.3628 | J8: USD | K8: =+VLOOKUP(J8,$W$2:$X$3,2,0)*I8 -> 1309.3628 | L8: Argentina | M8: Local Trials | O8: Janssen | P8: =K8 -> 1309.3628 | Q8: 45831 | S8: 40700 | T8: Revenues - Third Parties | W8: BRL | X8: 0.1814
A9: =+VLOOKUP(O9,'Selectable Table'!$D$2:$E$1048576,2,0) -> J & J | B9: 30726 | C9: Local Trials | D9: CNTO1959UCO3001_Anc_Returns | E9: 2025 | F9: 6 | G9: =+VLOOKUP(H9,Chi!#REF!,3,0) -> #REF! | H9: Storage of Returns (per Pallet) | I9: 523.76362 | J9: USD | K9: =+VLOOKUP(J9,$W$2:$X$3,2,0)*I9 -> 523.76362 | L9: Argentina | M9: Local Trials | O9: Janssen | P9: =K9 -> 523.76362 | Q9: 45831 | S9: 40700 | T9: Revenues - Third Parties
A10: =+VLOOKUP(O10,'Selectable Table'!$D$2:$E$1048576,2,0) -> J & J | B10: 30727 | C10: Local Trials | D10: AC-055-315_anc_returns | E10: 2025 | F10: 6 | G10: =+VLOOKUP(H10,Chi!#REF!,3,0) -> #REF! | H10: Freight - Returns | I10: 141.449 | J10: USD | K10: =+VLOOKUP(J10,$W$2:$X$3,2,0)*I10 -> 141.449 | L10: Argentina | M10: Local Trials | O10: Janssen | P10: =K10 -> 141.449 | Q10: 45831 | S10: 40700 | T10: Revenues - Third Parties
A11: =+VLOOKUP(O11,'Selectable Table'!$D$2:$E$1048576,2,0) -> J & J | B11: 30727 | C11: Local Trials | D11: AC-055-315_anc_returns | E11: 2025 | F11: 6 | G11: =+VLOOKUP(H11,Chi!#REF!,3,0) -> #REF! | H11: Non-Drug Storage Ambient (per Pallet) | I11: 218.22713 | J11: USD | K11: =+VLOOKUP(J11,$W$2:$X$3,2,0)*I11 -> 218.22713 | L11: Argentina | M11: Local Trials | O11: Janssen | P11: =K11 -> 218.22713 | Q11: 45831 | S11: 40700 | T11: Revenues - Third Parties
A12: =+VLOOKUP(O12,'Selectable Table'!$D$2:$E$1048576,2,0) -> J & J | B12: 30727 | C12: Local Trials | D12: AC-055-315_anc_returns | E12: 2025 | F12: 6 | G12: =+VLOOKUP(H12,Chi!#REF!,3,0) -> #REF! | H12: Reconciliation of Returns (per Hour) | I12: 61.103185 | J12: USD | K12: =+VLOOKUP(J12,$W$2:$X$3,2,0)*I12 -> 61.103185 | L12: Argentina | M12: Local Trials | O12: Janssen | P12: =K12 -> 61.103185 | Q12: 45831 | S12: 40700 | T12: Revenues - Third Parties
A13: =+VLOOKUP(O13,'Selectable Table'!$D$2:$E$1048576,2,0) -> J & J | B13: 30727 | C13: Local Trials | D13: AC-055-315_anc_returns | E13: 2025 | F13: 6 | G13: =+VLOOKUP(H13,Chi!#REF!,3,0) -> #REF! | H13: Returns Receipt (per Receipt) | I13: 320.78915 | J13: USD | K13: =+VLOOKUP(J13,$W$2:$X$3,2,0)*I13 -> 320.78915 | L13: Argentina | M13: Local Trials | O13: Janssen | P13: =K13 -> 320.78915 | Q13: 45831 | S13: 40700 | T13: Revenues - Third Parties
A14: =+VLOOKUP(O14,'Selectable Table'!$D$2:$E$1048576,2,0) -> J & J | B14: 30727 | C14: Local Trials | D14: AC-055-315_anc_returns | E14: 2025 | F14: 6 | G14: =+VLOOKUP(H14,Chi!#REF!,3,0) -> #REF! | H14: Storage Ambient (per Pallet) | I14: 218.22713 | J14: USD | K14: =+VLOOKUP(J14,$W$2:$X$3,2,0)*I14 -> 218.22713 | L14: Argentina | M14: Local Trials | O14: Janssen | P14: =K14 -> 218.22713 | Q14: 45831 | S14: 40700 | T14: Revenues - Third Parties
A15: =+VLOOKUP(O15,'Selectable Table'!$D$2:$E$1048576,2,0) -> J & J | B15: 30727 | C15: Local Trials | D15: AC-055-315_anc_returns | E15: 2025 | F15: 6 | G15: =+VLOOKUP(H15,Chi!#REF!,3,0) -> #REF! | H15: Storage of Returns (per Pallet) | I15: 523.76362 | J15: USD | K15: =+VLOOKUP(J15,$W$2:$X$3,2,0)*I15 -> 523.76362 | L15: Argentina | M15: Local Trials | O15: Janssen | P15: =K15 -> 523.76362 | Q15: 45831 | S15: 40700 | T15: Revenues - Third Parties
A16: =+VLOOKUP(O16,'Selectable Table'!$D$2:$E$1048576,2,0) -> J & J | B16: 30728 | C16: Local Trials | D16: 67652000PCR3002_anc_returns | E16: 2025 | F16: 6 | G16: =+VLOOKUP(H16,Chi!#REF!,3,0) -> #REF! | H16: Freight - Returns | I16: 382.5052 | J16: USD | K16: =+VLOOKUP(J16,$W$2:$X$3,2,0)*I16 -> 382.5052 | L16: Argentina | M16: Local Trials | O16: Janssen | P16: =K16 -> 382.5052 | Q16: 45831 | S16: 40700 | T16: Revenues - Third Parties
A17: =+VLOOKUP(O17,'Selectable Table'!$D$2:$E$1048576,2,0) -> J & J | B17: 30728 | C17: Local Trials | D17: 67652000PCR3002_anc_returns | E17: 2025 | F17: 6 | G17: =+VLOOKUP(H17,Chi!#REF!,3,0) -> #REF! | H17: Reconciliation of Returns (per Hour) | I17: 122.20637 | J17: USD | K17: =+VLOOKUP(J17,$W$2:$X$3,2,0)*I17 -> 122.20637 | L17: Argentina | M17: Local Trials | O17: Janssen | P17: =K17 -> 122.20637 | Q17: 45831 | S17: 40700 | T17: Revenues - Third Parties
A18: =+VLOOKUP(O18,'Selectable Table'!$D$2:$E$1048576,2,0) -> J & J | B18: 30728 | C18: Local Trials | D18: 67652000PCR3002_anc_returns | E18: 2025 | F18: 6 | G18: =+VLOOKUP(H18,Chi!#REF!,3,0) -> #REF! | H18: Returns Receipt (per Receipt) | I18: 320.78915 | J18: USD | K18: =+VLOOKUP(J18,$W$2:$X$3,2,0)*I18 -> 320.78915 | L18: Argentina | M18: Local Trials | O18: Janssen | P18: =K18 -> 320.78915 | Q18: 45831 | S18: 40700 | T18: Revenues - Third Parties
A19: =+VLOOKUP(O19,'Selectable Table'!$D$2:$E$1048576,2,0) -> J & J | B19: 30728 | C19: Local Trials | D19: 67652000PCR3002_anc_returns | E19: 2025 | F19: 6 | G19: =+VLOOKUP(H19,Chi!#REF!,3,0) -> #REF! | H19: Storage of Returns (per Pallet) | I19: 838.0218 | J19: USD | K19: =+VLOOKUP(J19,$W$2:$X$3,2,0)*I19 -> 838.0218 | L19: Argentina | M19: Local Trials | O19: Janssen | P19: =K19 -> 838.0218 | Q19: 45831 | S19: 40700 | T19: Revenues - Third Parties
A20: =+VLOOKUP(O20,'Selectable Table'!$D$2:$E$1048576,2,0) -> J & J | B20: 30729 | C20: Local Trials | D20: 73841937NSC3003_Anc_Returns | E20: 2025 | F20: 6 | G20: =+VLOOKUP(H20,Chi!#REF!,3,0) -> #REF! | H20: Non-Drug Storage Ambient (per Pallet) | I20: 218.22713 | J20: USD | K20: =+VLOOKUP(J20,$W$2:$X$3,2,0)*I20 -> 218.22713 | L20: Argentina | M20: Local Trials | O20: Janssen | P20: =K20 -> 218.22713 | Q20: 45831 | S20: 40700 | T20: Revenues - Third Parties
... A170: =+VLOOKUP(O170,'Selectable Table'!$D$2:$E$1048576,2,0) -> MERCK | B170: 30772 | C170: ARG FR# 58474 PO#: 8200873875 | D170: MK-2060-007 (Local) | E170: 2025 | F170: 6 | G170: =+VLOOKUP(H170,Chi!#REF!,3,0) -> #REF! | H170: Reconciliation of Returns (per Hour) | I170: 65.4368 | J170: USD | K170: =+VLOOKUP(J170,$W$2:$X$3,2,0)*I170 -> 65.4368 | L170: Argentina | M170: PO#: 8200873875 | O170: Merck Sharp and Dohme LLC | P170: =K170 -> 65.4368 | Q170: 45831 | S170: 40700 | T170: Revenues - Third Parties
A171: =+VLOOKUP(O171,'Selectable Table'!$D$2:$E$1048576,2,0) -> MERCK | B171: 30772 | C171: ARG FR# 58474 PO#: 8200873875 | D171: MK-2060-007 (Local) | E171: 2025 | F171: 6 | G171: Total Distribution | H171: Returns Receipt (per Receipt) | I171: 163.592 | J171: USD | K171: =+VLOOKUP(J171,$W$2:$X$3,2,0)*I171 -> 163.592 | L171: Argentina | M171: PO#: 8200873875 | O171: Merck Sharp and Dohme LLC | P171: =K171 -> 163.592 | Q171: 45831 | S171: 40700 | T171: Revenues - Third Parties
A172: =+VLOOKUP(O172,'Selectable Table'!$D$2:$E$1048576,2,0) -> MERCK | B172: 30772 | C172: ARG FR# 58474 PO#: 8200873875 | D172: MK-2060-007 (Local) | E172: 2025 | F172: 6 | G172: =+VLOOKUP(H172,Chi!#REF!,3,0) -> #REF! | H172: Storage of Returns (per Pallet) | I172: 462.8492 | J172: USD | K172: =+VLOOKUP(J172,$W$2:$X$3,2,0)*I172 -> 462.8492 | L172: Argentina | M172: PO#: 8200873875 | O172: Merck Sharp and Dohme LLC | P172: =K172 -> 462.8492 | Q172: 45831 | S172: 40700 | T172: Revenues - Third Parties
A173: =+VLOOKUP(O173,'Selectable Table'!$D$2:$E$1048576,2,0) -> MERCK | B173: 30773 | C173: FR# 58474 PO# 8200873875 | D173: MK-2140-003 (Local) | E173: 2025 | F173: 6 | G173: Total Return Drug | H173: Freight - Shipments | I173: 355.2197 | J173: USD | K173: =+VLOOKUP(J173,$W$2:$X$3,2,0)*I173 -> 355.2197 | L173: Argentina | M173: PO# 8200873875 | O173: Merck Sharp and Dohme LLC | P173: =K173 -> 355.2197 | Q173: 45831 | S173: 40700 | T173: Revenues - Third Parties
A174: =+VLOOKUP(O174,'Selectable Table'!$D$2:$E$1048576,2,0) -> MERCK | B174: 30773 | C174: FR# 58474 PO# 8200873875 | D174: MK-2140-003 (Local) | E174: 2025 | F174: 6 | G174: =+VLOOKUP(H174,Chi!#REF!,3,0) -> #REF! | H174: Reconciliation of Returns (per Hour) | I174: 65.4368 | J174: USD | K174: =+VLOOKUP(J174,$W$2:$X$3,2,0)*I174 -> 65.4368 | L174: Argentina | M174: PO# 8200873875 | O174: Merck Sharp and Dohme LLC | P174: =K174 -> 65.4368 | Q174: 45831 | S174: 40700 | T174: Revenues - Third Parties
A175: =+VLOOKUP(O175,'Selectable Table'!$D$2:$E$1048576,2,0) -> MERCK | B175: 30773 | C175: FR# 58474 PO# 8200873875 | D175: MK-2140-003 (Local) | E175: 2025 | F175: 6 | G175: =+VLOOKUP(H175,Chi!#REF!,3,0) -> #REF! | H175: Returns Receipt (per Receipt) | I175: 163.592 | J175: USD | K175: =+VLOOKUP(J175,$W$2:$X$3,2,0)*I175 -> 163.592 | L175: Argentina | M175: PO# 8200873875 | O175: Merck Sharp and Dohme LLC | P175: =K175 -> 163.592 | Q175: 45831 | S175: 40700 | T175: Revenues - Third Parties
A176: =+VLOOKUP(O176,'Selectable Table'!$D$2:$E$1048576,2,0) -> MERCK | B176: 30773 | C176: FR# 58474 PO# 8200873875 | D176: MK-2140-003 (Local) | E176: 2025 | F176: 6 | G176: Total Distribution | H176: Storage Ambient (per Pallet) | I176: 140.2269 | J176: USD | K176: =+VLOOKUP(J176,$W$2:$X$3,2,0)*I176 -> 140.2269 | L176: Argentina | M176: PO# 8200873875 | O176: Merck Sharp and Dohme LLC | P176: =K176 -> 140.2269 | Q176: 45831 | S176: 40700 | T176: Revenues - Third Parties
A177: =+VLOOKUP(O177,'Selectable Table'!$D$2:$E$1048576,2,0) -> MERCK | B177: 30773 | C177: FR# 58474 PO# 8200873875 | D177: MK-2140-003 (Local) | E177: 2025 | F177: 6 | G177: =+VLOOKUP(H177,Chi!#REF!,3,0) -> #REF! | H177: Storage of Returns (per Pallet) | I177: 115.7123 | J177: USD | K177: =+VLOOKUP(J177,$W$2:$X$3,2,0)*I177 -> 115.7123 | L177: Argentina | M177: PO# 8200873875 | O177: Merck Sharp and Dohme LLC | P177: =K177 -> 115.7123 | Q177: 45831 | S177: 40700 | T177: Revenues - Third Parties
A178: =+VLOOKUP(O178,'Selectable Table'!$D$2:$E$1048576,2,0) -> MERCK | B178: 30774 | C178: 58474 - ARG PO#8200873875 | D178: MK-1084-001 (Local) | E178: 2025 | F178: 6 | G178: =+VLOOKUP(H178,Chi!#REF!,3,0) -> #REF! | H178: Storage Ambient (per Pallet) | I178: 140.2269 | J178: USD | K178: =+VLOOKUP(J178,$W$2:$X$3,2,0)*I178 -> 140.2269 | L178: Argentina | M178: PO#8200873875 | O178: Merck Sharp and Dohme LLC | P178: =K178 -> 140.2269 | Q178: 45831 | S178: 40700 | T178: Revenues - Third Parties
A179: =+VLOOKUP(O179,'Selectable Table'!$D$2:$E$1048576,2,0) -> MERCK | B179: 30775 | C179: (ARG) PO 8200873875 | D179: MK-7684A-006 (Local) | E179: 2025 | F179: 6 | G179: =+VLOOKUP(H179,Chi!#REF!,3,0) -> #REF! | H179: Freight - Returns | I179: 395.2828 | J179: USD | K179: =+VLOOKUP(J179,$W$2:$X$3,2,0)*I179 -> 395.2828 | L179: Argentina | M179: PO 8200873875 | O179: Merck Sharp and Dohme LLC | P179: =K179 -> 395.2828 | Q179: 45831 | S179: 40700 | T179: Revenues - Third Parties
A180: =+VLOOKUP(O180,'Selectable Table'!$D$2:$E$1048576,2,0) -> MERCK | B180: 30775 | C180: (ARG) PO 8200873875 | D180: MK-7684A-006 (Local) | E180: 2025 | F180: 6 | G180: =+VLOOKUP(H180,Chi!#REF!,3,0) -> #REF! | H180: Storage Ambient (per Pallet) | I180: 560.9076 | J180: USD | K180: =+VLOOKUP(J180,$W$2:$X$3,2,0)*I180 -> 560.9076 | L180: Argentina | M180: PO 8200873875 | O180: Merck Sharp and Dohme LLC | P180: =K180 -> 560.9076 | Q180: 45831 | S180: 40700 | T180: Revenues - Third Parties
A181: =+VLOOKUP(O181,'Selectable Table'!$D$2:$E$1048576,2,0) -> MERCK | B181: 30775 | C181: (ARG) PO 8200873875 | D181: MK-7684A-006 (Local) | E181: 2025 | F181: 6 | G181: =+VLOOKUP(H181,Chi!#REF!,3,0) -> #REF! | H181: Storage of Labels Ambient (per Pallet) | I181: 115.7123 | J181: USD | K181: =+VLOOKUP(J181,$W$2:$X$3,2,0)*I181 -> 115.7123 | L181: Argentina | M181: PO 8200873875 | O181: Merck Sharp and Dohme LLC | P181: =K181 -> 115.7123 | Q181: 45831 | S181: 40700 | T181: Revenues - Third Parties
A182: =+VLOOKUP(O182,'Selectable Table'!$D$2:$E$1048576,2,0) -> MERCK | B182: 30775 | C182: (ARG) PO 8200873875 | D182: MK-7684A-006 (Local) | E182: 2025 | F182: 6 | G182: =+VLOOKUP(H182,Chi!#REF!,3,0) -> #REF! | H182: Storage of Returns (per Pallet) | I182: 231.4246 | J182: USD | K182: =+VLOOKUP(J182,$W$2:$X$3,2,0)*I182 -> 231.4246 | L182: Argentina | M182: PO 8200873875 | O182: Merck Sharp and Dohme LLC | P182: =K182 -> 231.4246 | Q182: 45831 | S182: 40700 | T182: Revenues - Third Parties
A183: =+VLOOKUP(O183,'Selectable Table'!$D$2:$E$1048576,2,0) -> MERCK | B183: 30775 | C183: (ARG) PO 8200873875 | D183: MK-7684A-006 (Local) | E183: 2025 | F183: 6 | G183: =+VLOOKUP(H183,Chi!#REF!,3,0) -> #REF! | H183: Storage Refrigerated (per Shelf) | I183: 420.6444 | J183: USD | K183: =+VLOOKUP(J183,$W$2:$X$3,2,0)*I183 -> 420.6444 | L183: Argentina | M183: PO 8200873875 | O183: Merck Sharp and Dohme LLC | P183: =K183 -> 420.6444 | Q183: 45831 | S183: 40700 | T183: Revenues - Third Parties
A184: =+VLOOKUP(O184,'Selectable Table'!$D$2:$E$1048576,2,0) -> MERCK | B184: 30776 | C184: (ARG) PO 8200873875 | D184: MK-7684A-007 (Local) | E184: 2025 | F184: 6 | G184: =+VLOOKUP(H184,Chi!#REF!,3,0) -> #REF! | H184: Freight - Returns | I184: 197.6414 | J184: USD | K184: =+VLOOKUP(J184,$W$2:$X$3,2,0)*I184 -> 197.6414 | L184: Argentina | M184: PO 8200873875 | O184: Merck Sharp and Dohme LLC | P184: =K184 -> 197.6414 | Q184: 45831 | S184: 40700 | T184: Revenues - Third Parties
A185: =+VLOOKUP(O185,'Selectable Table'!$D$2:$E$1048576,2,0) -> MERCK | B185: 30776 | C185: (ARG) PO 8200873875 | D185: MK-7684A-007 (Local) | E185: 2025 | F185: 6 | G185: =+VLOOKUP(H185,Chi!#REF!,3,0) -> #REF! | H185: Pick and Pack (Ambient) | I185: 151.9155 | J185: USD | K185: =+VLOOKUP(J185,$W$2:$X$3,2,0)*I185 -> 151.9155 | L185: Argentina | M185: PO 8200873875 | O185: Merck Sharp and Dohme LLC | P185: =K185 -> 151.9155 | Q185: 45831 | S185: 40700 | T185: Revenues - Third Parties
A186: =+VLOOKUP(O186,'Selectable Table'!$D$2:$E$1048576,2,0) -> MERCK | B186: 30776 | C186: (ARG) PO 8200873875 | D186: MK-7684A-007 (Local) | E186: 2025 | F186: 6 | G186: =+VLOOKUP(H186,Chi!#REF!,3,0) -> #REF! | H186: Reconciliation of Returns (per Hour) | I186: 65.4368 | J186: USD | K186: =+VLOOKUP(J186,$W$2:$X$3,2,0)*I186 -> 65.4368 | L186: Argentina | M186: PO 8200873875 | O186: Merck Sharp and Dohme LLC | P186: =K186 -> 65.4368 | Q186: 45831 | S186: 40700 | T186: Revenues - Third Parties
A187: =+VLOOKUP(O187,'Selectable Table'!$D$2:$E$1048576,2,0) -> MERCK | B187: 30776 | C187: (ARG) PO 8200873875 | D187: MK-7684A-007 (Local) | E187: 2025 | F187: 6 | G187: =+VLOOKUP(H187,Chi!#REF!,3,0) -> #REF! | H187: Returns Receipt (per Receipt) | I187: 163.592 | J187: USD | K187: =+VLOOKUP(J187,$W$2:$X$3,2,0)*I187 -> 163.592 | L187: Argentina | M187: PO 8200873875 | O187: Merck Sharp and Dohme LLC | P187: =K187 -> 163.592 | Q187: 45831 | S187: 40700 | T187: Revenues - Third Parties
A188: =+VLOOKUP(O188,'Selectable Table'!$D$2:$E$1048576,2,0) -> MERCK | B188: 30776 | C188: (ARG) PO 8200873875 | D188: MK-7684A-007 (Local) | E188: 2025 | F188: 6 | G188: =+VLOOKUP(H188,Chi!#REF!,3,0) -> #REF! | H188: Storage Ambient (per Pallet) | I188: 280.4538 | J188: USD | K188: =+VLOOKUP(J188,$W$2:$X$3,2,0)*I188 -> 280.4538 | L188: Argentina | M188: PO 8200873875 | O188: Merck Sharp and Dohme LLC | P188: =K188 -> 280.4538 | Q188: 45831 | S188: 40700 | T188: Revenues - Third Parties
... A211: =+VLOOKUP(O211,'Selectable Table'!$D$2:$E$1048576,2,0) -> MERCK | B211: 30782 | C211: (ARG) FR 58474 PO 8200873875 | D211: MK-7684A-010 (Local) | E211: 2025 | F211: 6 | G211: =+VLOOKUP(H211,Chi!#REF!,3,0) -> #REF! | H211: Freight - Returns | I211: 985.5329 | J211: USD | K211: =+VLOOKUP(J211,$W$2:$X$3,2,0)*I211 -> 985.5329 | L211: Argentina | M211: PO 8200873875 | O211: Merck Sharp and Dohme LLC | P211: =K211 -> 985.5329 | Q211: 45831 | S211: 40700 | T211: Revenues - Third Parties
...

Sheet TrasnP (2)
A1: CUSTOMER | B1: INVOICE_. | C1: FISHER_JOB | D1: PROTOCOL | E1: yr | F1: period | G1: PRODUCT | H1: SUB-PRODUCT | I1: DocValue | J1: DOC_CURRENCY | K1: USD Value | L1: FISHER_LOC | M1: PO. | N1: doccode | O1: el4_name | P1: Home Currency | Q1: docdate | R1: ref1 | S1: el2 | T1: el2_name | U1: el3 | W1: DOC_CURRENCY | X1: BS May | Z1: Sponsor de Revenue | AT1: NO TOCAR
A2: =+VLOOKUP(O2,'Selectable Table'!D:E,2,0) -> ELI LILLY | B2: 5415166 | C2: PARG57830 | D2: I5T-MC-AACO (CAM) | E2: 2025 | F2: 6 | G2: totalStorage | H2: Storage | I2: -22.932 | J2: USD | K2: =+VLOOKUP(J2,$W$2:$X$7,2,0)*I2 -> -22.932 | L2: BSLATAMTP | M2: 4200451914 | O2: ELI LILLY AND CO | P2: =K2 -> -22.932 | Q2: 45831 | S2: 40700 | T2: Revenues - Third Parties | W2: USD | X2: 1
A3: =+VLOOKUP(O3,'Selectable Table'!D:E,2,0) -> ELI LILLY | B3: 5415166 | C3: PARG57830 | D3: I5T-MC-AACO (CAM) | E3: 2025 | F3: 6 | G3: totalDistribution | H3: Distribution | I3: 3.9 | J3: USD | K3: =+VLOOKUP(J3,$W$2:$X$7,2,0)*I3 -> 3.9 | L3: BSLATAMTP | M3: 4200451914 | O3: ELI LILLY AND CO | P3: =K3 -> 3.9 | Q3: 45831 | S3: 40700 | T3: Revenues - Third Parties | W3: EUR | X3: 1.12694
A4: =+VLOOKUP(O4,'Selectable Table'!D:E,2,0) -> OTH CUST | B4: 5413135 | C4: PARG87129 | D4: J1I-MC-GZBP (CAM) | E4: 2025 | F4: 6 | G4: totalFreight | H4: Freight | I4: -840 | J4: USD | K4: =+VLOOKUP(J4,$W$2:$X$7,2,0)*I4 -> -840 | L4: BSLATAMTP | M4: E005473054 | O4: FISHER CLINICAL SERV | P4: =K4 -> -840 | Q4: 45824 | S4: 40700 | T4: Revenues - Third Parties | W4: CHF | X4: 1.20482
A5: =+VLOOKUP(O5,'Selectable Table'!D:E,2,0) -> DEBIOPHARM | B5: 5415165 | C5: PARG84773 | D5: J1I-MC-GZBP (CAM) | E5: 2025 | F5: 6 | G5: totalStorage | H5: Storage | I5: -262.74 | J5: USD | K5: =+VLOOKUP(J5,$W$2:$X$7,2,0)*I5 -> -262.74 | L5: BSLATAMTP | M5: PO-23-0179 | O5: DEBIOPHARM INTL SA | P5: =K5 -> -262.74 | Q5: 45831 | S5: 40700 | T5: Revenues - Third Parties | W5: CLP | X5: 0.00106
A6: =+VLOOKUP(O6,'Selectable Table'!D:E,2,0) -> ELI LILLY | B6: 5415166 | C6: PARG57830 | D6: J1I-MC-GZBP (CAM) | E6: 2025 | F6: 6 | G6: totalDistribution | H6: Distribution | I6: -15537.984 | J6: USD | K6: =+VLOOKUP(J6,$W$2:$X$7,2,0)*I6 -> -15537.984 | L6: BSLATAMTP | M6: 4200451914 | O6: ELI LILLY AND CO | P6: =K6 -> -15537.984 | Q6: 45831 | S6: 40700 | T6: Revenues - Third Parties | W6: GBP | X6: 1.33461
A7: =+VLOOKUP(O7,'Selectable Table'!D:E,2,0) -> ELI LILLY | B7: 5415166 | C7: PARG57830 | D7: J1I-MC-GZBP (CAM) | E7: 2025 | F7: 6 | G7: totalDistribution | H7: Distribution | I7: -441.44 | J7: USD | K7: =+VLOOKUP(J7,$W$2:$X$7,2,0)*I7 -> -441.44 | L7: BSLATAMTP | M7: 4200451914 | O7: ELI LILLY AND CO | P7: =K7 -> -441.44 | Q7: 45831 | S7: 40700 | T7: Revenues - Third Parties | W7: BRL | X7: 0.17643
A8: =+VLOOKUP(O8,'Selectable Table'!D:E,2,0) -> ELI LILLY | B8: 5415166 | C8: PARG57830 | D8: J1I-MC-GZQD (CAM) | E8: 2025 | F8: 6 | G8: totalStorage | H8: Storage | I8: -5591.32 | J8: USD | K8: =+VLOOKUP(J8,$W$2:$X$7,2,0)*I8 -> -5591.32 | L8: BSLATAMTP | M8: 4200451914 | O8: ELI LILLY AND CO | P8: =K8 -> -5591.32 | Q8: 45831 | S8: 40700 | T8: Revenues - Third Parties
A9: =+VLOOKUP(O9,'Selectable Table'!D:E,2,0) -> ELI LILLY | B9: 5415166 | C9: PARG57830 | D9: J1I-MC-GZQD (CAM) | E9: 2025 | F9: 6 | G9: totalDistribution | H9: Distribution | I9: -6936.6 | J9: USD | K9: =+VLOOKUP(J9,$W$2:$X$7,2,0)*I9 -> -6936.6 | L9: BSLATAMTP | M9: 4200451914 | O9: ELI LILLY AND CO | P9: =K9 -> -6936.6 | Q9: 45831 | S9: 40700 | T9: Revenues - Third Parties
